Workbook

Sheet 說明
A1: Global AR 問卷:回收統計(Google 試算表版)
A3: 使用方式
A4: 1. 在「夥伴名單」填入全部要發送的夥伴(代碼、名稱、國家、身份)。代碼要和發給夥伴的一致。
A5: 2. 在「設定」分頁 B6 貼上 Google 表單的「回覆試算表」網址(建立表單時程式會印出)。B7 是回覆工作表名稱,通常是「表單回應 1」。
A6: 3. 「回覆資料」A1 會自動從回覆試算表匯入資料。第一次出現 #REF! 時,點該儲存格,按「允許存取」。之後資料即時更新,不需要貼上。
A7: 4. 「總覽」看回收率;「各題統計」看每題選項人數與比例(含子公司/合資、代理行分開)。
A9: 注意
A10: • 統計靠標題列開頭的「A1. 」這類題號前綴找欄位,表單題目文字請勿改動前綴。
A11: • Google 表單把多選題答案用「, 」(逗號加空格)連接,本範本依此計算。
A12: • 同一夥伴填多份時,「夥伴名單」的回覆份數會標紅;請在回覆試算表中刪除舊的一列再統計。
A13: • 單選題「其他(自填)」人數 = 作答人數減去各選項人數;多選題的自填內容請直接在回覆資料查看。
A14: • 支援最多 999 份回覆、約 100 欄。不要手動改「回覆資料」以外分頁的公式。

Sheet 總覽
A1: 回收總覽
A3: 已發送夥伴數 | B3: =COUNTA(夥伴名單!$A$2:$A$301)
A4: 已回收夥伴數 | B4: =COUNTIF(夥伴名單!$F$2:$F$301,"是")
A5: 回收率 | B5: =IF(B3=0,"",B4/B3)
A6: 總回覆份數 | B6: =IF(設定!$B$3=0,0,SUMPRODUCT((INDEX(回覆資料!$A$2:$CZ$1000,0,設定!$B$3)<>"")*1))
A7: 代碼不在名單的回覆數 | B7: =IF(設定!$B$4=0,0,SUMPRODUCT((INDEX(回覆資料!$A$2:$CZ$1000,0,設定!$B$4)<>"")*(COUNTIF(夥伴名單!$A$2:$A$301,INDEX(回覆資料!$A$2:$CZ$1000,0,設定!$B$4))=0)))
A8: 有重複回覆的夥伴數 | B8: =COUNTIF(夥伴名單!$G$2:$G$301,">1")
A10: 身份 | B10: 已發送 | C10: 已回收 | D10: 回收率 | E10: 回覆份數
A11: 子公司/合資 | B11: =COUNTIF(夥伴名單!$D$2:$D$301,A11) | C11: =COUNTIFS(夥伴名單!$D$2:$D$301,A11,夥伴名單!$F$2:$F$301,"是") | D11: =IF(B11=0,"",C11/B11) | E11: =IF(設定!$B$3=0,0,SUMPRODUCT((INDEX(回覆資料!$A$2:$CZ$1000,0,設定!$B$3)=設定!$B$1)*1))
A12: 代理行 | B12: =COUNTIF(夥伴名單!$D$2:$D$301,A12) | C12: =COUNTIFS(夥伴名單!$D$2:$D$301,A12,夥伴名單!$F$2:$F$301,"是") | D12: =IF(B12=0,"",C12/B12) | E12: =IF(設定!$B$3=0,0,SUMPRODUCT((INDEX(回覆資料!$A$2:$CZ$1000,0,設定!$B$3)=設定!$B$2)*1))

Sheet 各題統計
A1: 題號 | B1: 題目 / 選項 | C1: 題型 | D1: 全部人數 | E1: 全部 % | F1: 子公司/合資 | G1: 代理行 | H1: 欄位位置
A2: R0 | B2: 貴單位屬於哪一類?(作答人數) | C2: 單選 | D2: =IF($H$2=0,0,SUMPRODUCT((INDEX(回覆資料!$A$2:$CZ$1000,0,$H$2)<>"")*1)) | F2: =IF(OR($H$2=0,設定!$B$3=0),0,SUMPRODUCT((INDEX(回覆資料!$A$2:$CZ$1000,0,$H$2)<>"")*(INDEX(回覆資料!$A$2:$CZ$1000,0,設定!$B$3)=設定!$B$1))) | G2: =IF(OR($H$2=0,設定!$B$3=0),0,SUMPRODUCT((INDEX(回覆資料!$A$2:$CZ$1000,0,$H$2)<>"")*(INDEX(回覆資料!$A$2:$CZ$1000,0,設定!$B$3)=設定!$B$2))) | H2: =IFERROR(MATCH(A2&". *",回覆資料!$A$1:$CZ$1,0),0)
A3: R0 | B3: 子公司 / 合資公司(例如 YMA、YMC) | D3: =IF($H$2=0,0,SUMPRODUCT(ISNUMBER(FIND(", "&$B3&", ",", "&INDEX(回覆資料!$A$2:$CZ$1000,0,$H$2)&", "))*1)) | E3: =IF($D$2=0,"",D3/$D$2) | F3: =IF(OR($H$2=0,設定!$B$3=0),0,SUMPRODUCT(ISNUMBER(FIND(", "&$B3&", ",", "&INDEX(回覆資料!$A$2:$CZ$1000,0,$H$2)&", "))*(INDEX(回覆資料!$A$2:$CZ$1000,0,設定!$B$3)=設定!$B$1))) | G3: =IF(OR($H$2=0,設定!$B$3=0),0,SUMPRODUCT(ISNUMBER(FIND(", "&$B3&", ",", "&INDEX(回覆資料!$A$2:$CZ$1000,0,$H$2)&", "))*(INDEX(回覆資料!$A$2:$CZ$1000,0,設定!$B$3)=設定!$B$2)))
A4: R0 | B4: 代理行(Agent) | D4: =IF($H$2=0,0,SUMPRODUCT(ISNUMBER(FIND(", "&$B4&", ",", "&INDEX(回覆資料!$A$2:$CZ$1000,0,$H$2)&", "))*1)) | E4: =IF($D$2=0,"",D4/$D$2) | F4: =IF(OR($H$2=0,設定!$B$3=0),0,SUMPRODUCT(ISNUMBER(FIND(", "&$B4&", ",", "&INDEX(回覆資料!$A$2:$CZ$1000,0,$H$2)&", "))*(INDEX(回覆資料!$A$2:$CZ$1000,0,設定!$B$3)=設定!$B$1))) | G4: =IF(OR($H$2=0,設定!$B$3=0),0,SUMPRODUCT(ISNUMBER(FIND(", "&$B4&", ",", "&INDEX(回覆資料!$A$2:$CZ$1000,0,$H$2)&", "))*(INDEX(回覆資料!$A$2:$CZ$1000,0,設定!$B$3)=設定!$B$2)))
A5: A1 | B5: 前端收款作業涵蓋哪些項目?(作答人數) | C5: 多選 | D5: =IF($H$5=0,0,SUMPRODUCT((INDEX(回覆資料!$A$2:$CZ$1000,0,$H$5)<>"")*1)) | F5: =IF(OR($H$5=0,設定!$B$3=0),0,SUMPRODUCT((INDEX(回覆資料!$A$2:$CZ$1000,0,$H$5)<>"")*(INDEX(回覆資料!$A$2:$CZ$1000,0,設定!$B$3)=設定!$B$1))) | G5: =IF(OR($H$5=0,設定!$B$3=0),0,SUMPRODUCT((INDEX(回覆資料!$A$2:$CZ$1000,0,$H$5)<>"")*(INDEX(回覆資料!$A$2:$CZ$1000,0,設定!$B$3)=設定!$B$2))) | H5: =IFERROR(MATCH(A5&". *",回覆資料!$A$1:$CZ$1,0),0)
A6: A1 | B6: 進口運費 | D6: =IF($H$5=0,0,SUMPRODUCT(ISNUMBER(FIND(", "&$B6&", ",", "&INDEX(回覆資料!$A$2:$CZ$1000,0,$H$5)&", "))*1)) | E6: =IF($D$5=0,"",D6/$D$5) | F6: =IF(OR($H$5=0,設定!$B$3=0),0,SUMPRODUCT(ISNUMBER(FIND(", "&$B6&", ",", "&INDEX(回覆資料!$A$2:$CZ$1000,0,$H$5)&", "))*(INDEX(回覆資料!$A$2:$CZ$1000,0,設定!$B$3)=設定!$B$1))) | G6: =IF(OR($H$5=0,設定!$B$3=0),0,SUMPRODUCT(ISNUMBER(FIND(", "&$B6&", ",", "&INDEX(回覆資料!$A$2:$CZ$1000,0,$H$5)&", "))*(INDEX(回覆資料!$A$2:$CZ$1000,0,設定!$B$3)=設定!$B$2)))
A7: A1 | B7: 出口運費 | D7: =IF($H$5=0,0,SUMPRODUCT(ISNUMBER(FIND(", "&$B7&", ",", "&INDEX(回覆資料!$A$2:$CZ$1000,0,$H$5)&", "))*1)) | E7: =IF($D$5=0,"",D7/$D$5) | F7: =IF(OR($H$5=0,設定!$B$3=0),0,SUMPRODUCT(ISNUMBER(FIND(", "&$B7&", ",", "&INDEX(回覆資料!$A$2:$CZ$1000,0,$H$5)&", "))*(INDEX(回覆資料!$A$2:$CZ$1000,0,設定!$B$3)=設定!$B$1))) | G7: =IF(OR($H$5=0,設定!$B$3=0),0,SUMPRODUCT(ISNUMBER(FIND(", "&$B7&", ",", "&INDEX(回覆資料!$A$2:$CZ$1000,0,$H$5)&", "))*(INDEX(回覆資料!$A$2:$CZ$1000,0,設定!$B$3)=設定!$B$2)))
A8: A1 | B8: Manifest Charge | D8: =IF($H$5=0,0,SUMPRODUCT(ISNUMBER(FIND(", "&$B8&", ",", "&INDEX(回覆資料!$A$2:$CZ$1000,0,$H$5)&", "))*1)) | E8: =IF($D$5=0,"",D8/$D$5) | F8: =IF(OR($H$5=0,設定!$B$3=0),0,SUMPRODUCT(ISNUMBER(FIND(", "&$B8&", ",", "&INDEX(回覆資料!$A$2:$CZ$1000,0,$H$5)&", "))*(INDEX(回覆資料!$A$2:$CZ$1000,0,設定!$B$3)=設定!$B$1))) | G8: =IF(OR($H$5=0,設定!$B$3=0),0,SUMPRODUCT(ISNUMBER(FIND(", "&$B8&", ",", "&INDEX(回覆資料!$A$2:$CZ$1000,0,$H$5)&", "))*(INDEX(回覆資料!$A$2:$CZ$1000,0,設定!$B$3)=設定!$B$2)))
A9: A1 | B9: Non-Manifest Charge | D9: =IF($H$5=0,0,SUMPRODUCT(ISNUMBER(FIND(", "&$B9&", ",", "&INDEX(回覆資料!$A$2:$CZ$1000,0,$H$5)&", "))*1)) | E9: =IF($D$5=0,"",D9/$D$5) | F9: =IF(OR($H$5=0,設定!$B$3=0),0,SUMPRODUCT(ISNUMBER(FIND(", "&$B9&", ",", "&INDEX(回覆資料!$A$2:$CZ$1000,0,$H$5)&", "))*(INDEX(回覆資料!$A$2:$CZ$1000,0,設定!$B$3)=設定!$B$1))) | G9: =IF(OR($H$5=0,設定!$B$3=0),0,SUMPRODUCT(ISNUMBER(FIND(", "&$B9&", ",", "&INDEX(回覆資料!$A$2:$CZ$1000,0,$H$5)&", "))*(INDEX(回覆資料!$A$2:$CZ$1000,0,設定!$B$3)=設定!$B$2)))
A10: A1 | B10: Local Charge | D10: =IF($H$5=0,0,SUMPRODUCT(ISNUMBER(FIND(", "&$B10&", ",", "&INDEX(回覆資料!$A$2:$CZ$1000,0,$H$5)&", "))*1)) | E10: =IF($D$5=0,"",D10/$D$5) | F10: =IF(OR($H$5=0,設定!$B$3=0),0,SUMPRODUCT(ISNUMBER(FIND(", "&$B10&", ",", "&INDEX(回覆資料!$A$2:$CZ$1000,0,$H$5)&", "))*(INDEX(回覆資料!$A$2:$CZ$1000,0,設定!$B$3)=設定!$B$1))) | G10: =IF(OR($H$5=0,設定!$B$3=0),0,SUMPRODUCT(ISNUMBER(FIND(", "&$B10&", ",", "&INDEX(回覆資料!$A$2:$CZ$1000,0,$H$5)&", "))*(INDEX(回覆資料!$A$2:$CZ$1000,0,設定!$B$3)=設定!$B$2)))
A11: A1 | B11: 非運費收入 | D11: =IF($H$5=0,0,SUMPRODUCT(ISNUMBER(FIND(", "&$B11&", ",", "&INDEX(回覆資料!$A$2:$CZ$1000,0,$H$5)&", "))*1)) | E11: =IF($D$5=0,"",D11/$D$5) | F11: =IF(OR($H$5=0,設定!$B$3=0),0,SUMPRODUCT(ISNUMBER(FIND(", "&$B11&", ",", "&INDEX(回覆資料!$A$2:$CZ$1000,0,$H$5)&", "))*(INDEX(回覆資料!$A$2:$CZ$1000,0,設定!$B$3)=設定!$B$1))) | G11: =IF(OR($H$5=0,設定!$B$3=0),0,SUMPRODUCT(ISNUMBER(FIND(", "&$B11&", ",", "&INDEX(回覆資料!$A$2:$CZ$1000,0,$H$5)&", "))*(INDEX(回覆資料!$A$2:$CZ$1000,0,設定!$B$3)=設定!$B$2)))
A12: A1 | B12: 第三地付款 | D12: =IF($H$5=0,0,SUMPRODUCT(ISNUMBER(FIND(", "&$B12&", ",", "&INDEX(回覆資料!$A$2:$CZ$1000,0,$H$5)&", "))*1)) | E12: =IF($D$5=0,"",D12/$D$5) | F12: =IF(OR($H$5=0,設定!$B$3=0),0,SUMPRODUCT(ISNUMBER(FIND(", "&$B12&", ",", "&INDEX(回覆資料!$A$2:$CZ$1000,0,$H$5)&", "))*(INDEX(回覆資料!$A$2:$CZ$1000,0,設定!$B$3)=設定!$B$1))) | G12: =IF(OR($H$5=0,設定!$B$3=0),0,SUMPRODUCT(ISNUMBER(FIND(", "&$B12&", ",", "&INDEX(回覆資料!$A$2:$CZ$1000,0,$H$5)&", "))*(INDEX(回覆資料!$A$2:$CZ$1000,0,設定!$B$3)=設定!$B$2)))
A13: A1 | B13: (多選題的「其他」自填內容請到回覆資料查看)
A14: A2 | B14: 進口與出口的收款作業,在地與 ICBO 如何分工?(作答人數) | C14: 單選 | D14: =IF($H$14=0,0,SUMPRODUCT((INDEX(回覆資料!$A$2:$CZ$1000,0,$H$14)<>"")*1)) | F14: =IF(OR($H$14=0,設定!$B$3=0),0,SUMPRODUCT((INDEX(回覆資料!$A$2:$CZ$1000,0,$H$14)<>"")*(INDEX(回覆資料!$A$2:$CZ$1000,0,設定!$B$3)=設定!$B$1))) | G14: =IF(OR($H$14=0,設定!$B$3=0),0,SUMPRODUCT((INDEX(回覆資料!$A$2:$CZ$1000,0,$H$14)<>"")*(INDEX(回覆資料!$A$2:$CZ$1000,0,設定!$B$3)=設定!$B$2))) | H14: =IFERROR(MATCH(A14&". *",回覆資料!$A$1:$CZ$1,0),0)
A15: A2 | B15: 全部由在地處理 | D15: =IF($H$14=0,0,SUMPRODUCT(ISNUMBER(FIND(", "&$B15&", ",", "&INDEX(回覆資料!$A$2:$CZ$1000,0,$H$14)&", "))*1)) | E15: =IF($D$14=0,"",D15/$D$14) | F15: =IF(OR($H$14=0,設定!$B$3=0),0,SUMPRODUCT(ISNUMBER(FIND(", "&$B15&", ",", "&INDEX(回覆資料!$A$2:$CZ$1000,0,$H$14)&", "))*(INDEX(回覆資料!$A$2:$CZ$1000,0,設定!$B$3)=設定!$B$1))) | G15: =IF(OR($H$14=0,設定!$B$3=0),0,SUMPRODUCT(ISNUMBER(FIND(", "&$B15&", ",", "&INDEX(回覆資料!$A$2:$CZ$1000,0,$H$14)&", "))*(INDEX(回覆資料!$A$2:$CZ$1000,0,設定!$B$3)=設定!$B$2)))
A16: A2 | B16: 收款在地、銷帳由 ICBO 集中處理 | D16: =IF($H$14=0,0,SUMPRODUCT(ISNUMBER(FIND(", "&$B16&", ",", "&INDEX(回覆資料!$A$2:$CZ$1000,0,$H$14)&", "))*1)) | E16: =IF($D$14=0,"",D16/$D$14) | F16: =IF(OR($H$14=0,設定!$B$3=0),0,SUMPRODUCT(ISNUMBER(FIND(", "&$B16&", ",", "&INDEX(回覆資料!$A$2:$CZ$1000,0,$H$14)&", "))*(INDEX(回覆資料!$A$2:$CZ$1000,0,設定!$B$3)=設定!$B$1))) | G16: =IF(OR($H$14=0,設定!$B$3=0),0,SUMPRODUCT(ISNUMBER(FIND(", "&$B16&", ",", "&INDEX(回覆資料!$A$2:$CZ$1000,0,$H$14)&", "))*(INDEX(回覆資料!$A$2:$CZ$1000,0,設定!$B$3)=設定!$B$2)))
A17: A2 | B17: 收款與銷帳皆由 ICBO 集中,在地僅聯繫客戶 | D17: =IF($H$14=0,0,SUMPRODUCT(ISNUMBER(FIND(", "&$B17&", ",", "&INDEX(回覆資料!$A$2:$CZ$1000,0,$H$14)&", "))*1)) | E17: =IF($D$14=0,"",D17/$D$14) | F17: =IF(OR($H$14=0,設定!$B$3=0),0,SUMPRODUCT(ISNUMBER(FIND(", "&$B17&", ",", "&INDEX(回覆資料!$A$2:$CZ$1000,0,$H$14)&", "))*(INDEX(回覆資料!$A$2:$CZ$1000,0,設定!$B$3)=設定!$B$1))) | G17: =IF(OR($H$14=0,設定!$B$3=0),0,SUMPRODUCT(ISNUMBER(FIND(", "&$B17&", ",", "&INDEX(回覆資料!$A$2:$CZ$1000,0,$H$14)&", "))*(INDEX(回覆資料!$A$2:$CZ$1000,0,設定!$B$3)=設定!$B$2)))
A18: A2 | B18: 進口與出口分工不同 | D18: =IF($H$14=0,0,SUMPRODUCT(ISNUMBER(FIND(", "&$B18&", ",", "&INDEX(回覆資料!$A$2:$CZ$1000,0,$H$14)&", "))*1)) | E18: =IF($D$14=0,"",D18/$D$14) | F18: =IF(OR($H$14=0,設定!$B$3=0),0,SUMPRODUCT(ISNUMBER(FIND(", "&$B18&", ",", "&INDEX(回覆資料!$A$2:$CZ$1000,0,$H$14)&", "))*(INDEX(回覆資料!$A$2:$CZ$1000,0,設定!$B$3)=設定!$B$1))) | G18: =IF(OR($H$14=0,設定!$B$3=0),0,SUMPRODUCT(ISNUMBER(FIND(", "&$B18&", ",", "&INDEX(回覆資料!$A$2:$CZ$1000,0,$H$14)&", "))*(INDEX(回覆資料!$A$2:$CZ$1000,0,設定!$B$3)=設定!$B$2)))
A19: A2 | B19: 其他(自填) | D19: =D14-SUM(D15:D18) | E19: =IF($D$14=0,"",D19/$D$14) | F19: =F14-SUM(F15:F18) | G19: =G14-SUM(G15:G18)
A20: A3 | B20: 收款與銷帳由哪些單位負責?(作答人數) | C20: 多選 | D20: =IF($H$20=0,0,SUMPRODUCT((INDEX(回覆資料!$A$2:$CZ$1000,0,$H$20)<>"")*1)) | F20: =IF(OR($H$20=0,設定!$B$3=0),0,SUMPRODUCT((INDEX(回覆資料!$A$2:$CZ$1000,0,$H$20)<>"")*(INDEX(回覆資料!$A$2:$CZ$1000,0,設定!$B$3)=設定!$B$1))) | G20: =IF(OR($H$20=0,設定!$B$3=0),0,SUMPRODUCT((INDEX(回覆資料!$A$2:$CZ$1000,0,$H$20)<>"")*(INDEX(回覆資料!$A$2:$CZ$1000,0,設定!$B$3)=設定!$B$2))) | H20: =IFERROR(MATCH(A20&". *",回覆資料!$A$1:$CZ$1,0),0)
A21: A3 | B21: YMA-NJ | D21: =IF($H$20=0,0,SUMPRODUCT(ISNUMBER(FIND(", "&$B21&", ",", "&INDEX(回覆資料!$A$2:$CZ$1000,0,$H$20)&", "))*1)) | E21: =IF($D$20=0,"",D21/$D$20) | F21: =IF(OR($H$20=0,設定!$B$3=0),0,SUMPRODUCT(ISNUMBER(FIND(", "&$B21&", ",", "&INDEX(回覆資料!$A$2:$CZ$1000,0,$H$20)&", "))*(INDEX(回覆資料!$A$2:$CZ$1000,0,設定!$B$3)=設定!$B$1))) | G21: =IF(OR($H$20=0,設定!$B$3=0),0,SUMPRODUCT(ISNUMBER(FIND(", "&$B21&", ",", "&INDEX(回覆資料!$A$2:$CZ$1000,0,$H$20)&", "))*(INDEX(回覆資料!$A$2:$CZ$1000,0,設定!$B$3)=設定!$B$2)))
A22: A3 | B22: LAX office | D22: =IF($H$20=0,0,SUMPRODUCT(ISNUMBER(FIND(", "&$B22&", ",", "&INDEX(回覆資料!$A$2:$CZ$1000,0,$H$20)&", "))*1)) | E22: =IF($D$20=0,"",D22/$D$20) | F22: =IF(OR($H$20=0,設定!$B$3=0),0,SUMPRODUCT(ISNUMBER(FIND(", "&$B22&", ",", "&INDEX(回覆資料!$A$2:$CZ$1000,0,$H$20)&", "))*(INDEX(回覆資料!$A$2:$CZ$1000,0,設定!$B$3)=設定!$B$1))) | G22: =IF(OR($H$20=0,設定!$B$3=0),0,SUMPRODUCT(ISNUMBER(FIND(", "&$B22&", ",", "&INDEX(回覆資料!$A$2:$CZ$1000,0,$H$20)&", "))*(INDEX(回覆資料!$A$2:$CZ$1000,0,設定!$B$3)=設定!$B$2)))
A23: A3 | B23: ICBO-DSA | D23: =IF($H$20=0,0,SUMPRODUCT(ISNUMBER(FIND(", "&$B23&", ",", "&INDEX(回覆資料!$A$2:$CZ$1000,0,$H$20)&", "))*1)) | E23: =IF($D$20=0,"",D23/$D$20) | F23: =IF(OR($H$20=0,設定!$B$3=0),0,SUMPRODUCT(ISNUMBER(FIND(", "&$B23&", ",", "&INDEX(回覆資料!$A$2:$CZ$1000,0,$H$20)&", "))*(INDEX(回覆資料!$A$2:$CZ$1000,0,設定!$B$3)=設定!$B$1))) | G23: =IF(OR($H$20=0,設定!$B$3=0),0,SUMPRODUCT(ISNUMBER(FIND(", "&$B23&", ",", "&INDEX(回覆資料!$A$2:$CZ$1000,0,$H$20)&", "))*(INDEX(回覆資料!$A$2:$CZ$1000,0,設定!$B$3)=設定!$B$2)))
A24: A3 | B24: ICBO-NSA | D24: =IF($H$20=0,0,SUMPRODUCT(ISNUMBER(FIND(", "&$B24&", ",", "&INDEX(回覆資料!$A$2:$CZ$1000,0,$H$20)&", "))*1)) | E24: =IF($D$20=0,"",D24/$D$20) | F24: =IF(OR($H$20=0,設定!$B$3=0),0,SUMPRODUCT(ISNUMBER(FIND(", "&$B24&", ",", "&INDEX(回覆資料!$A$2:$CZ$1000,0,$H$20)&", "))*(INDEX(回覆資料!$A$2:$CZ$1000,0,設定!$B$3)=設定!$B$1))) | G24: =IF(OR($H$20=0,設定!$B$3=0),0,SUMPRODUCT(ISNUMBER(FIND(", "&$B24&", ",", "&INDEX(回覆資料!$A$2:$CZ$1000,0,$H$20)&", "))*(INDEX(回覆資料!$A$2:$CZ$1000,0,設定!$B$3)=設定!$B$2)))
A25: A3 | B25: HSC | D25: =IF($H$20=0,0,SUMPRODUCT(ISNUMBER(FIND(", "&$B25&", ",", "&INDEX(回覆資料!$A$2:$CZ$1000,0,$H$20)&", "))*1)) | E25: =IF($D$20=0,"",D25/$D$20) | F25: =IF(OR($H$20=0,設定!$B$3=0),0,SUMPRODUCT(ISNUMBER(FIND(", "&$B25&", ",", "&INDEX(回覆資料!$A$2:$CZ$1000,0,$H$20)&", "))*(INDEX(回覆資料!$A$2:$CZ$1000,0,設定!$B$3)=設定!$B$1))) | G25: =IF(OR($H$20=0,設定!$B$3=0),0,SUMPRODUCT(ISNUMBER(FIND(", "&$B25&", ",", "&INDEX(回覆資料!$A$2:$CZ$1000,0,$H$20)&", "))*(INDEX(回覆資料!$A$2:$CZ$1000,0,設定!$B$3)=設定!$B$2)))
A26: A3 | B26: (多選題的「其他」自填內容請到回覆資料查看)
A27: A4 | B27: 日班與夜班如何分工及交接?(作答人數) | C27: 單選 | D27: =IF($H$27=0,0,SUMPRODUCT((INDEX(回覆資料!$A$2:$CZ$1000,0,$H$27)<>"")*1)) | F27: =IF(OR($H$27=0,設定!$B$3=0),0,SUMPRODUCT((INDEX(回覆資料!$A$2:$CZ$1000,0,$H$27)<>"")*(INDEX(回覆資料!$A$2:$CZ$1000,0,設定!$B$3)=設定!$B$1))) | G27: =IF(OR($H$27=0,設定!$B$3=0),0,SUMPRODUCT((INDEX(回覆資料!$A$2:$CZ$1000,0,$H$27)<>"")*(INDEX(回覆資料!$A$2:$CZ$1000,0,設定!$B$3)=設定!$B$2))) | H27: =IFERROR(MATCH(A27&". *",回覆資料!$A$1:$CZ$1,0),0)
A28: A4 | B28: 無日夜班分工 | D28: =IF($H$27=0,0,SUMPRODUCT(ISNUMBER(FIND(", "&$B28&", ",", "&INDEX(回覆資料!$A$2:$CZ$1000,0,$H$27)&", "))*1)) | E28: =IF($D$27=0,"",D28/$D$27) | F28: =IF(OR($H$27=0,設定!$B$3=0),0,SUMPRODUCT(ISNUMBER(FIND(", "&$B28&", ",", "&INDEX(回覆資料!$A$2:$CZ$1000,0,$H$27)&", "))*(INDEX(回覆資料!$A$2:$CZ$1000,0,設定!$B$3)=設定!$B$1))) | G28: =IF(OR($H$27=0,設定!$B$3=0),0,SUMPRODUCT(ISNUMBER(FIND(", "&$B28&", ",", "&INDEX(回覆資料!$A$2:$CZ$1000,0,$H$27)&", "))*(INDEX(回覆資料!$A$2:$CZ$1000,0,設定!$B$3)=設定!$B$2)))
A29: A4 | B29: 有分工,書面交接並以系統追蹤 | D29: =IF($H$27=0,0,SUMPRODUCT(ISNUMBER(FIND(", "&$B29&", ",", "&INDEX(回覆資料!$A$2:$CZ$1000,0,$H$27)&", "))*1)) | E29: =IF($D$27=0,"",D29/$D$27) | F29: =IF(OR($H$27=0,設定!$B$3=0),0,SUMPRODUCT(ISNUMBER(FIND(", "&$B29&", ",", "&INDEX(回覆資料!$A$2:$CZ$1000,0,$H$27)&", "))*(INDEX(回覆資料!$A$2:$CZ$1000,0,設定!$B$3)=設定!$B$1))) | G29: =IF(OR($H$27=0,設定!$B$3=0),0,SUMPRODUCT(ISNUMBER(FIND(", "&$B29&", ",", "&INDEX(回覆資料!$A$2:$CZ$1000,0,$H$27)&", "))*(INDEX(回覆資料!$A$2:$CZ$1000,0,設定!$B$3)=設定!$B$2)))
A30: A4 | B30: 有分工,僅以 Email / 口頭交接 | D30: =IF($H$27=0,0,SUMPRODUCT(ISNUMBER(FIND(", "&$B30&", ",", "&INDEX(回覆資料!$A$2:$CZ$1000,0,$H$27)&", "))*1)) | E30: =IF($D$27=0,"",D30/$D$27) | F30: =IF(OR($H$27=0,設定!$B$3=0),0,SUMPRODUCT(ISNUMBER(FIND(", "&$B30&", ",", "&INDEX(回覆資料!$A$2:$CZ$1000,0,$H$27)&", "))*(INDEX(回覆資料!$A$2:$CZ$1000,0,設定!$B$3)=設定!$B$1))) | G30: =IF(OR($H$27=0,設定!$B$3=0),0,SUMPRODUCT(ISNUMBER(FIND(", "&$B30&", ",", "&INDEX(回覆資料!$A$2:$CZ$1000,0,$H$27)&", "))*(INDEX(回覆資料!$A$2:$CZ$1000,0,設定!$B$3)=設定!$B$2)))
A31: A4 | B31: 有分工,無交接機制 | D31: =IF($H$27=0,0,SUMPRODUCT(ISNUMBER(FIND(", "&$B31&", ",", "&INDEX(回覆資料!$A$2:$CZ$1000,0,$H$27)&", "))*1)) | E31: =IF($D$27=0,"",D31/$D$27) | F31: =IF(OR($H$27=0,設定!$B$3=0),0,SUMPRODUCT(ISNUMBER(FIND(", "&$B31&", ",", "&INDEX(回覆資料!$A$2:$CZ$1000,0,$H$27)&", "))*(INDEX(回覆資料!$A$2:$CZ$1000,0,設定!$B$3)=設定!$B$1))) | G31: =IF(OR($H$27=0,設定!$B$3=0),0,SUMPRODUCT(ISNUMBER(FIND(", "&$B31&", ",", "&INDEX(回覆資料!$A$2:$CZ$1000,0,$H$27)&", "))*(INDEX(回覆資料!$A$2:$CZ$1000,0,設定!$B$3)=設定!$B$2)))
A32: A5 | B32: 每月帳單數約為多少?(作答人數) | C32: 單選 | D32: =IF($H$32=0,0,SUMPRODUCT((INDEX(回覆資料!$A$2:$CZ$1000,0,$H$32)<>"")*1)) | F32: =IF(OR($H$32=0,設定!$B$3=0),0,SUMPRODUCT((INDEX(回覆資料!$A$2:$CZ$1000,0,$H$32)<>"")*(INDEX(回覆資料!$A$2:$CZ$1000,0,設定!$B$3)=設定!$B$1))) | G32: =IF(OR($H$32=0,設定!$B$3=0),0,SUMPRODUCT((INDEX(回覆資料!$A$2:$CZ$1000,0,$H$32)<>"")*(INDEX(回覆資料!$A$2:$CZ$1000,0,設定!$B$3)=設定!$B$2))) | H32: =IFERROR(MATCH(A32&". *",回覆資料!$A$1:$CZ$1,0),0)
A33: A5 | B33: 未滿 500 | D33: =IF($H$32=0,0,SUMPRODUCT(ISNUMBER(FIND(", "&$B33&", ",", "&INDEX(回覆資料!$A$2:$CZ$1000,0,$H$32)&", "))*1)) | E33: =IF($D$32=0,"",D33/$D$32) | F33: =IF(OR($H$32=0,設定!$B$3=0),0,SUMPRODUCT(ISNUMBER(FIND(", "&$B33&", ",", "&INDEX(回覆資料!$A$2:$CZ$1000,0,$H$32)&", "))*(INDEX(回覆資料!$A$2:$CZ$1000,0,設定!$B$3)=設定!$B$1))) | G33: =IF(OR($H$32=0,設定!$B$3=0),0,SUMPRODUCT(ISNUMBER(FIND(", "&$B33&", ",", "&INDEX(回覆資料!$A$2:$CZ$1000,0,$H$32)&", "))*(INDEX(回覆資料!$A$2:$CZ$1000,0,設定!$B$3)=設定!$B$2)))
A34: A5 | B34: 500–2,000 | D34: =IF($H$32=0,0,SUMPRODUCT(ISNUMBER(FIND(", "&$B34&", ",", "&INDEX(回覆資料!$A$2:$CZ$1000,0,$H$32)&", "))*1)) | E34: =IF($D$32=0,"",D34/$D$32) | F34: =IF(OR($H$32=0,設定!$B$3=0),0,SUMPRODUCT(ISNUMBER(FIND(", "&$B34&", ",", "&INDEX(回覆資料!$A$2:$CZ$1000,0,$H$32)&", "))*(INDEX(回覆資料!$A$2:$CZ$1000,0,設定!$B$3)=設定!$B$1))) | G34: =IF(OR($H$32=0,設定!$B$3=0),0,SUMPRODUCT(ISNUMBER(FIND(", "&$B34&", ",", "&INDEX(回覆資料!$A$2:$CZ$1000,0,$H$32)&", "))*(INDEX(回覆資料!$A$2:$CZ$1000,0,設定!$B$3)=設定!$B$2)))
A35: A5 | B35: 2,001–5,000 | D35: =IF($H$32=0,0,SUMPRODUCT(ISNUMBER(FIND(", "&$B35&", ",", "&INDEX(回覆資料!$A$2:$CZ$1000,0,$H$32)&", "))*1)) | E35: =IF($D$32=0,"",D35/$D$32) | F35: =IF(OR($H$32=0,設定!$B$3=0),0,SUMPRODUCT(ISNUMBER(FIND(", "&$B35&", ",", "&INDEX(回覆資料!$A$2:$CZ$1000,0,$H$32)&", "))*(INDEX(回覆資料!$A$2:$CZ$1000,0,設定!$B$3)=設定!$B$1))) | G35: =IF(OR($H$32=0,設定!$B$3=0),0,SUMPRODUCT(ISNUMBER(FIND(", "&$B35&", ",", "&INDEX(回覆資料!$A$2:$CZ$1000,0,$H$32)&", "))*(INDEX(回覆資料!$A$2:$CZ$1000,0,設定!$B$3)=設定!$B$2)))
A36: A5 | B36: 5,001–10,000 | D36: =IF($H$32=0,0,SUMPRODUCT(ISNUMBER(FIND(", "&$B36&", ",", "&INDEX(回覆資料!$A$2:$CZ$1000,0,$H$32)&", "))*1)) | E36: =IF($D$32=0,"",D36/$D$32) | F36: =IF(OR($H$32=0,設定!$B$3=0),0,SUMPRODUCT(ISNUMBER(FIND(", "&$B36&", ",", "&INDEX(回覆資料!$A$2:$CZ$1000,0,$H$32)&", "))*(INDEX(回覆資料!$A$2:$CZ$1000,0,設定!$B$3)=設定!$B$1))) | G36: =IF(OR($H$32=0,設定!$B$3=0),0,SUMPRODUCT(ISNUMBER(FIND(", "&$B36&", ",", "&INDEX(回覆資料!$A$2:$CZ$1000,0,$H$32)&", "))*(INDEX(回覆資料!$A$2:$CZ$1000,0,設定!$B$3)=設定!$B$2)))
A37: A5 | B37: 10,001–50,000 | D37: =IF($H$32=0,0,SUMPRODUCT(ISNUMBER(FIND(", "&$B37&", ",", "&INDEX(回覆資料!$A$2:$CZ$1000,0,$H$32)&", "))*1)) | E37: =IF($D$32=0,"",D37/$D$32) | F37: =IF(OR($H$32=0,設定!$B$3=0),0,SUMPRODUCT(ISNUMBER(FIND(", "&$B37&", ",", "&INDEX(回覆資料!$A$2:$CZ$1000,0,$H$32)&", "))*(INDEX(回覆資料!$A$2:$CZ$1000,0,設定!$B$3)=設定!$B$1))) | G37: =IF(OR($H$32=0,設定!$B$3=0),0,SUMPRODUCT(ISNUMBER(FIND(", "&$B37&", ",", "&INDEX(回覆資料!$A$2:$CZ$1000,0,$H$32)&", "))*(INDEX(回覆資料!$A$2:$CZ$1000,0,設定!$B$3)=設定!$B$2)))
A38: A5 | B38: 超過 50,000 | D38: =IF($H$32=0,0,SUMPRODUCT(ISNUMBER(FIND(", "&$B38&", ",", "&INDEX(回覆資料!$A$2:$CZ$1000,0,$H$32)&", "))*1)) | E38: =IF($D$32=0,"",D38/$D$32) | F38: =IF(OR($H$32=0,設定!$B$3=0),0,SUMPRODUCT(ISNUMBER(FIND(", "&$B38&", ",", "&INDEX(回覆資料!$A$2:$CZ$1000,0,$H$32)&", "))*(INDEX(回覆資料!$A$2:$CZ$1000,0,設定!$B$3)=設定!$B$1))) | G38: =IF(OR($H$32=0,設定!$B$3=0),0,SUMPRODUCT(ISNUMBER(FIND(", "&$B38&", ",", "&INDEX(回覆資料!$A$2:$CZ$1000,0,$H$32)&", "))*(INDEX(回覆資料!$A$2:$CZ$1000,0,設定!$B$3)=設定!$B$2)))
A39: A6 | B39: 每月收款及銷帳筆數約為多少?(作答人數) | C39: 單選 | D39: =IF($H$39=0,0,SUMPRODUCT((INDEX(回覆資料!$A$2:$CZ$1000,0,$H$39)<>"")*1)) | F39: =IF(OR($H$39=0,設定!$B$3=0),0,SUMPRODUCT((INDEX(回覆資料!$A$2:$CZ$1000,0,$H$39)<>"")*(INDEX(回覆資料!$A$2:$CZ$1000,0,設定!$B$3)=設定!$B$1))) | G39: =IF(OR($H$39=0,設定!$B$3=0),0,SUMPRODUCT((INDEX(回覆資料!$A$2:$CZ$1000,0,$H$39)<>"")*(INDEX(回覆資料!$A$2:$CZ$1000,0,設定!$B$3)=設定!$B$2))) | H39: =IFERROR(MATCH(A39&". *",回覆資料!$A$1:$CZ$1,0),0)
A40: A6 | B40: 未滿 500 | D40: =IF($H$39=0,0,SUMPRODUCT(ISNUMBER(FIND(", "&$B40&", ",", "&INDEX(回覆資料!$A$2:$CZ$1000,0,$H$39)&", "))*1)) | E40: =IF($D$39=0,"",D40/$D$39) | F40: =IF(OR($H$39=0,設定!$B$3=0),0,SUMPRODUCT(ISNUMBER(FIND(", "&$B40&", ",", "&INDEX(回覆資料!$A$2:$CZ$1000,0,$H$39)&", "))*(INDEX(回覆資料!$A$2:$CZ$1000,0,設定!$B$3)=設定!$B$1))) | G40: =IF(OR($H$39=0,設定!$B$3=0),0,SUMPRODUCT(ISNUMBER(FIND(", "&$B40&", ",", "&INDEX(回覆資料!$A$2:$CZ$1000,0,$H$39)&", "))*(INDEX(回覆資料!$A$2:$CZ$1000,0,設定!$B$3)=設定!$B$2)))
...

Sheet 設定
A1: 子公司/合資選項文字 | B1: 子公司 / 合資公司(例如 YMA、YMC)
A2: 代理行選項文字 | B2: 代理行(Agent)
A3: R0 所在欄 | B3: =IFERROR(MATCH("R0. *",回覆資料!$A$1:$CZ$1,0),0)
A4: 夥伴代碼所在欄 | B4: =IFERROR(MATCH("P1. *",回覆資料!$A$1:$CZ$1,0),0)
A5: 說明 | B5: 選項文字須與表單的 R0 選項完全一致;一般不需修改
A6: 回覆試算表網址 | B6: (請貼上 Google 表單的回覆試算表網址)
A7: 回覆工作表名稱 | B7: 表單回應 1

Sheet 夥伴名單
A1: 夥伴代碼 | B1: 夥伴名稱 | C1: 國家 | D1: 身份 | E1: 負責人 | F1: 已回覆 | G1: 回覆份數
F2: =IF(A2="","",IF(G2>0,"是","否")) | G2: =IF(A2="","",IF(設定!$B$4=0,0,COUNTIF(INDEX(回覆資料!$A$2:$CZ$1000,0,設定!$B$4),A2)))
F3: =IF(A3="","",IF(G3>0,"是","否")) | G3: =IF(A3="","",IF(設定!$B$4=0,0,COUNTIF(INDEX(回覆資料!$A$2:$CZ$1000,0,設定!$B$4),A3)))
F4: =IF(A4="","",IF(G4>0,"是","否")) | G4: =IF(A4="","",IF(設定!$B$4=0,0,COUNTIF(INDEX(回覆資料!$A$2:$CZ$1000,0,設定!$B$4),A4)))
F5: =IF(A5="","",IF(G5>0,"是","否")) | G5: =IF(A5="","",IF(設定!$B$4=0,0,COUNTIF(INDEX(回覆資料!$A$2:$CZ$1000,0,設定!$B$4),A5)))
F6: =IF(A6="","",IF(G6>0,"是","否")) | G6: =IF(A6="","",IF(設定!$B$4=0,0,COUNTIF(INDEX(回覆資料!$A$2:$CZ$1000,0,設定!$B$4),A6)))
F7: =IF(A7="","",IF(G7>0,"是","否")) | G7: =IF(A7="","",IF(設定!$B$4=0,0,COUNTIF(INDEX(回覆資料!$A$2:$CZ$1000,0,設定!$B$4),A7)))
F8: =IF(A8="","",IF(G8>0,"是","否")) | G8: =IF(A8="","",IF(設定!$B$4=0,0,COUNTIF(INDEX(回覆資料!$A$2:$CZ$1000,0,設定!$B$4),A8)))
F9: =IF(A9="","",IF(G9>0,"是","否")) | G9: =IF(A9="","",IF(設定!$B$4=0,0,COUNTIF(INDEX(回覆資料!$A$2:$CZ$1000,0,設定!$B$4),A9)))
F10: =IF(A10="","",IF(G10>0,"是","否")) | G10: =IF(A10="","",IF(設定!$B$4=0,0,COUNTIF(INDEX(回覆資料!$A$2:$CZ$1000,0,設定!$B$4),A10)))
F11: =IF(A11="","",IF(G11>0,"是","否")) | G11: =IF(A11="","",IF(設定!$B$4=0,0,COUNTIF(INDEX(回覆資料!$A$2:$CZ$1000,0,設定!$B$4),A11)))
F12: =IF(A12="","",IF(G12>0,"是","否")) | G12: =IF(A12="","",IF(設定!$B$4=0,0,COUNTIF(INDEX(回覆資料!$A$2:$CZ$1000,0,設定!$B$4),A12)))
F13: =IF(A13="","",IF(G13>0,"是","否")) | G13: =IF(A13="","",IF(設定!$B$4=0,0,COUNTIF(INDEX(回覆資料!$A$2:$CZ$1000,0,設定!$B$4),A13)))
... F301: =IF(A301="","",IF(G301>0,"是","否")) | G301: =IF(A301="","",IF(設定!$B$4=0,0,COUNTIF(INDEX(回覆資料!$A$2:$CZ$1000,0,設定!$B$4),A301)))

Sheet 回覆資料
A1: =IFERROR(IMPORTRANGE(設定!$B$6,"'"&設定!$B$7&"'!A1:CZ1000"),"請在「設定」貼上回覆試算表網址並允許存取")
